2025-09-07 14:37:45,996 - goqii_eda - INFO - ================================================================================
2025-09-07 14:37:45,996 - goqii_eda - INFO - GOQII HEALTH DATA EDA PROTOCOL - DUAL OUTPUT ANALYSIS
2025-09-07 14:37:45,996 - goqii_eda - INFO - ================================================================================
2025-09-07 14:37:45,996 - goqii_eda - INFO - Input Directory: ./input
2025-09-07 14:37:45,996 - goqii_eda - INFO - Output Directory: ./processed
2025-09-07 14:37:45,996 - goqii_eda - INFO - Pipeline Started: 2025-09-07 14:37:45
2025-09-07 14:37:45,996 - goqii_eda - INFO - 
üìÇ STEP 1: Data Loading and Discovery
2025-09-07 14:37:45,996 - goqii_eda - INFO - --------------------------------------------------
2025-09-07 14:37:45,998 - goqii_eda - ERROR - ‚ùå Pipeline failed with error: 'total_files'
2025-09-07 14:37:45,998 - goqii_eda - ERROR - Full error traceback:
Traceback (most recent call last):
  File "/Users/jatindangi/Desktop/wearables/wearables/main.py", line 132, in run_eda_pipeline
    raw_data, loading_report = load_goqii_data(input_dir)
  File "/Users/jatindangi/Desktop/wearables/wearables/src/data_loader.py", line 532, in load_goqii_data
    summary = loader.get_loading_summary()
  File "/Users/jatindangi/Desktop/wearables/wearables/src/data_loader.py", line 477, in get_loading_summary
    'participants_by_file_count': summary_df['total_files'].value_counts().to_dict(),
  File "/Library/Frameworks/Python.framework/Versions/3.10/lib/python3.10/site-packages/pandas/core/frame.py", line 4107, in __getitem__
    indexer = self.columns.get_loc(key)
  File "/Library/Frameworks/Python.framework/Versions/3.10/lib/python3.10/site-packages/pandas/core/indexes/range.py", line 417, in get_loc
    raise KeyError(key)
KeyError: 'total_files'
